{
  "email": "jkoenig72@gmail.com",
  "language": "english",
  "products": [],
  "rfp_file": "QuestionsA1_-_Sheet1.csv",
  "additional_docs": [
    "10_A1_Telekom_Austria_Group_Request_for_Information_for_SME_Engagement_Platform_Instructions_to_Vendors.docx.pdf",
    "20_a_RFI_SME_Engagement_Platform_Business_Use_Case_Requirements.docx"
  ],
  "submitted_at": "2025-05-20 18:12:24",
  "started_at": "2025-05-20 19:55:45",
  "completed_at": "2025-05-20 19:56:23",
  "result_file": "RFP_Results_c735e60a96c87644.csv",
  "status": "processing",
  "error": "Process exited with code -6: 2025-05-20 19:55:48,745 [INFO] Running in web mode for job c735e60a96c87644\n2025-05-20 19:55:48,745 [INFO] Using Google Sheet ID from command line: 1Ri42Zi1vz4WlRJEAJUx9tf3veZVpR6KgwrlHm9wqnXE\n2025-05-20 19:55:48,745 [INFO] English language selected, translation disabled\n2025-05-20 19:55:48,745 [INFO] Initializing LLM provider: llamacpp (model: mistral-small3.1)\n2025-05-20 19:56:19,076 [INFO] Using customer context folder: job_c735e60a96c87644\n2025-05-20 19:56:19,076 [INFO] Creating index for customer folder: job_c735e60a96c87644\n2025-05-20 19:56:19,844 [INFO] Loaded PDF: 10_A1_Telekom_Austria_Group_Request_for_Information_for_SME_Engagement_Platform_Instructions_to_Vendors.docx.pdf (23 pages)\n2025-05-20 19:56:19,921 [INFO] Loaded DOCX: 20_a_RFI_SME_Engagement_Platform_Business_Use_Case_Requirements.docx (1 pages)\n2025-05-20 19:56:19,946 [INFO] Using CPU for embeddings (GPU disabled)\n2025-05-20 19:56:20,327 [ERROR] Error creating Customer DB index: Failed to import transformers.models.auto.modeling_auto because of the following error (look up to see its traceback):\nFailed to import transformers.generation.utils because of the following error (look up to see its traceback):\nnumpy.dtype size changed, may indicate binary incompatibility. Expected 96 from C header, got 88 from PyObject\n2025-05-20 19:56:20,327 [INFO] Saved customer index to /home/fritz/customer_indices/job_c735e60a96c87644_index\n2025-05-20 19:56:20,327 [INFO] Successfully created customer index: /home/fritz/customer_indices/job_c735e60a96c87644_index\n2025-05-20 19:56:20,327 [INFO] Using default product list: ['Sales Cloud', 'Service Cloud', 'Marketing Cloud', 'Platform', 'Experience Cloud', 'Communications Cloud', 'Data Cloud', 'Agentforce', 'MuleSoft']\n2025-05-20 19:56:20,327 [INFO] Initializing Google Sheet with ID: 1Ri42Zi1vz4WlRJEAJUx9tf3veZVpR6KgwrlHm9wqnXE\n2025-05-20 19:56:21,280 [INFO] Processing 10 records starting from row 3\n2025-05-20 19:56:21,280 [INFO] Output columns: {'answer': 8, 'compliance': 7}\n2025-05-20 19:56:21,280 [INFO] Initializing embedding manager with model: intfloat/e5-large-v2\n/home/fritz/llms-env/llmrag/rfp/main.py:528: DeprecationWarning: Retrievers must implement abstract `_get_relevant_documents` method instead of `get_relevant_documents`\n  class DummyRetriever(BaseRetriever):\n/home/fritz/llms-env/llmrag/rfp/main.py:528: DeprecationWarning: Retrievers must implement abstract `_aget_relevant_documents` method instead of `aget_relevant_documents`\n  class DummyRetriever(BaseRetriever):\n2025-05-20 19:56:21,282 [INFO] Starting question processing\n2025-05-20 19:56:21,282 [INFO] Found 10 indices in /home/fritz/RAG/indexes\n2025-05-20 19:56:21,282 [INFO]   salesforce: /home/fritz/RAG/indexes/salesforce_index\n2025-05-20 19:56:21,282 [INFO]   experience_cloud: /home/fritz/RAG/indexes/experience_cloud_index\n2025-05-20 19:56:21,282 [INFO]   platform: /home/fritz/RAG/indexes/platform_index\n2025-05-20 19:56:21,282 [INFO]   data_cloud: /home/fritz/RAG/indexes/data_cloud_index\n2025-05-20 19:56:21,282 [INFO]   communications_cloud: /home/fritz/RAG/indexes/communications_cloud_index\n2025-05-20 19:56:21,282 [INFO]   sales_cloud: /home/fritz/RAG/indexes/sales_cloud_index\n2025-05-20 19:56:21,282 [INFO]   agentforce: /home/fritz/RAG/indexes/agentforce_index\n2025-05-20 19:56:21,282 [INFO]   mulesoft: /home/fritz/RAG/indexes/mulesoft_index\n2025-05-20 19:56:21,282 [INFO]   marketing_cloud: /home/fritz/RAG/indexes/marketing_cloud_index\n2025-05-20 19:56:21,282 [INFO]   service_cloud: /home/fritz/RAG/indexes/service_cloud_index\n2025-05-20 19:56:21,282 [INFO] Using main salesforce index for no products\n2025-05-20 19:56:21,282 [INFO] Using GPU for embeddings: NVIDIA GeForce RTX 5070\n2025-05-20 19:56:21,287 [ERROR] \u274c Failed to process row 3: Failed to import transformers.models.auto.modeling_auto because of the following error (look up to see its traceback):\nFailed to import transformers.generation.utils because of the following error (look up to see its traceback):\nnumpy.dtype size changed, may indicate binary incompatibility. Expected 96 from C header, got 88 from PyObject\n2025-05-20 19:56:21,290 [INFO] Using GPU for embeddings: NVIDIA GeForce RTX 5070\n2025-05-20 19:56:21,293 [ERROR] \u274c Failed to process row 4: Failed to import transformers.models.auto.modeling_auto because of the following error (look up to see its traceback):\nFailed to import transformers.generation.utils because of the following error (look up to see its traceback):\nnumpy.dtype size changed, may indicate binary incompatibility. Expected 96 from C header, got 88 from PyObject\n2025-05-20 19:56:21,295 [INFO] Using GPU for embeddings: NVIDIA GeForce RTX 5070\n2025-05-20 19:56:21,298 [ERROR] \u274c Failed to process row 5: Failed to import transformers.models.auto.modeling_auto because of the following error (look up to see its traceback):\nFailed to import transformers.generation.utils because of the following error (look up to see its traceback):\nnumpy.dtype size changed, may indicate binary incompatibility. Expected 96 from C header, got 88 from PyObject\n2025-05-20 19:56:21,299 [INFO] Using GPU for embeddings: NVIDIA GeForce RTX 5070\n2025-05-20 19:56:21,302 [ERROR] \u274c Failed to process row 6: Failed to import transformers.models.auto.modeling_auto because of the following error (look up to see its traceback):\nFailed to import transformers.generation.utils because of the following error (look up to see its traceback):\nnumpy.dtype size changed, may indicate binary incompatibility. Expected 96 from C header, got 88 from PyObject\n2025-05-20 19:56:21,304 [INFO] Using GPU for embeddings: NVIDIA GeForce RTX 5070\n2025-05-20 19:56:21,306 [ERROR] \u274c Failed to process row 7: Failed to import transformers.models.auto.modeling_auto because of the following error (look up to see its traceback):\nFailed to import transformers.generation.utils because of the following error (look up to see its traceback):\nnumpy.dtype size changed, may indicate binary incompatibility. Expected 96 from C header, got 88 from PyObject\n2025-05-20 19:56:21,308 [INFO] Using GPU for embeddings: NVIDIA GeForce RTX 5070\n2025-05-20 19:56:21,310 [ERROR] \u274c Failed to process row 8: Failed to import transformers.models.auto.modeling_auto because of the following error (look up to see its traceback):\nFailed to import transformers.generation.utils because of the following error (look up to see its traceback):\nnumpy.dtype size changed, may indicate binary incompatibility. Expected 96 from C header, got 88 from PyObject\n2025-05-20 19:56:21,312 [INFO] Using GPU for embeddings: NVIDIA GeForce RTX 5070\n2025-05-20 19:56:21,314 [ERROR] \u274c Failed to process row 9: Failed to import transformers.models.auto.modeling_auto because of the following error (look up to see its traceback):\nFailed to import transformers.generation.utils because of the following error (look up to see its traceback):\nnumpy.dtype size changed, may indicate binary incompatibility. Expected 96 from C header, got 88 from PyObject\n2025-05-20 19:56:21,316 [INFO] Using GPU for embeddings: NVIDIA GeForce RTX 5070\n2025-05-20 19:56:21,318 [ERROR] \u274c Failed to process row 10: Failed to import transformers.models.auto.modeling_auto because of the following error (look up to see its traceback):\nFailed to import transformers.generation.utils because of the following error (look up to see its traceback):\nnumpy.dtype size changed, may indicate binary incompatibility. Expected 96 from C header, got 88 from PyObject\n2025-05-20 19:56:21,320 [INFO] Using GPU for embeddings: NVIDIA GeForce RTX 5070\n2025-05-20 19:56:21,323 [ERROR] \u274c Failed to process row 11: Failed to import transformers.models.auto.modeling_auto because of the following error (look up to see its traceback):\nFailed to import transformers.generation.utils because of the following error (look up to see its traceback):\nnumpy.dtype size changed, may indicate binary incompatibility. Expected 96 from C header, got 88 from PyObject\n2025-05-20 19:56:21,324 [INFO] Using GPU for embeddings: NVIDIA GeForce RTX 5070\n2025-05-20 19:56:21,327 [ERROR] \u274c Failed to process row 12: Failed to import transformers.models.auto.modeling_auto because of the following error (look up to see its traceback):\nFailed to import transformers.generation.utils because of the following error (look up to see its traceback):\nnumpy.dtype size changed, may indicate binary incompatibility. Expected 96 from C header, got 88 from PyObject\n2025-05-20 19:56:21,328 [INFO] RFI/RFP response processing completed successfully.\nTraceback (most recent call last):\n  File \"/home/fritz/llms-env/llmrag/rfp/main.py\", line 919, in <module>\n    sys.exit(exit_code)\n    ^^^\nNameError: name 'sys' is not defined. Did you forget to import 'sys'?\nFatal Python error: _enter_buffered_busy: could not acquire lock for <_io.BufferedReader name='<stdin>'> at interpreter shutdown, possibly due to daemon threads\nPython runtime state: finalizing (tstate=0x0000000000ba5048)\n\nCurrent thread 0x000079c94df35140 (most recent call first):\n  <no Python frame>\n"
}